2020-01-20 14:00:53,774 - __main__ - INFO - config file found
2020-01-20 14:00:53,776 - __main__ - INFO - Successfully read config data
2020-01-20 14:00:53,776 - __main__ - INFO - Shutting down DNA
2020-01-20 14:01:09,489 - __main__ - ERROR - Shutdown failed. Exiting...
Traceback (most recent call last):
  File "C:\Users\kbasavarajap\Python\Python37\lib\site-packages\paramiko\channel.py", line 699, in recv
    out = self.in_buffer.read(nbytes, self.timeout)
  File "C:\Users\kbasavarajap\Python\Python37\lib\site-packages\paramiko\buffered_pipe.py", line 164, in read
    raise PipeTimeout()
paramiko.buffered_pipe.PipeTimeout

During handling of the above exception, another exception occurred:

Traceback (most recent call last):
  File "C:/Users/kbasavarajap/PycharmProjects/Discovery_measurement/venv/Scripts/Discovery_using_DB.py", line 86, in shutdown_DNA
    interact.expect ( PROMPT )
  File "C:\Users\kbasavarajap\Python\Python37\lib\site-packages\paramiko_expect.py", line 144, in expect
    current_buffer = self.channel.recv(self.buffer_size)
  File "C:\Users\kbasavarajap\Python\Python37\lib\site-packages\paramiko\channel.py", line 701, in recv
    raise socket.timeout()
socket.timeout
2020-01-20 14:01:09,510 - __main__ - INFO - 2020-01-20 14:01:09.510218
