2020-01-17 14:16:45,294|__main__|INFO|config file found
2020-01-17 14:16:45,294|__main__|ERROR|Error reading config file
Traceback (most recent call last):
  File "C:/Users/kbasavarajap/PycharmProjects/Discovery_measurement/configtest.py", line 37, in <module>
    RUN_PURPOSE=config['RUN']['PURPOSE']
  File "C:\Users\kbasavarajap\Python\Python37\Lib\configparser.py", line 958, in __getitem__
    raise KeyError(key)
KeyError: 'RUN'
