2020-01-17 16:51:12,574 - __main__ - ERROR - DB queries failed
Traceback (most recent call last):
  File "C:/Users/kbasavarajap/PycharmProjects/Discovery_measurement/venv/Scripts/Discovery_using_DB.py", line 208, in <module>
    periodic_db(DNA_IP=DNA_IP, DNA_DB_USERNAME = DNA_DB_USERNAME, DNA_DB_PASSWD=DNA_DB_PASSWD, interval=int(INTERVAL), total_duration=int(TOTAL_DURATION))
  File "C:/Users/kbasavarajap/PycharmProjects/Discovery_measurement/venv/Scripts/Discovery_using_DB.py", line 188, in periodic_db
    sqlcursor.execute(data)
  File "C:\Users\kbasavarajap\Python\Python37\lib\site-packages\mysql\connector\cursor.py", line 551, in execute
    self._handle_result(self._connection.cmd_query(stmt))
  File "C:\Users\kbasavarajap\Python\Python37\lib\site-packages\mysql\connector\connection.py", line 490, in cmd_query
    result = self._handle_result(self._send_cmd(ServerCmd.QUERY, query))
  File "C:\Users\kbasavarajap\Python\Python37\lib\site-packages\mysql\connector\connection.py", line 395, in _handle_result
    raise errors.get_exception(packet)
mysql.connector.errors.ProgrammingError: 1064 (42000): You have an error in your SQL syntax; check the manual that corresponds to your MariaDB server version for the right syntax to use near '.5.129)' at line 1
